Workbook

Sheet TEMP

Sheet HISTORICAL INFORMATION
A1: ACUTAAS CHEMICALS LIMITED
A2: HISTORICAL FINANCIAL INFORMATION
A4: INCOME STATEMENT | H4: 2021 | I4: =H4+1 -> 2022 | J4: =I4+1 -> 2023 | K4: =J4+1 -> 2024 | L4: =K4+1 -> 2025 | M4: =L4+1 -> 2026 | N4: =M4+1 -> 2027 | O4: =N4+1 -> 2028 | P4: =O4+1 -> 2029 | ... R4: =Q4+1 -> 2031
D5: Income
D6: Revenue from operations | H6: 34060.79 | I6: 52013.5 | J6: 61673.45 | K6: 71747.45 | L6: 100687.55
D7: Other Income | H7: 137.97 | I7: 276.23 | J7: 431.98 | K7: 749.09 | L7: 1692.94
D8: Total Income | H8: 34198.76 | I8: 52289.73 | J8: 62105.43 | K8: 72496.54 | L8: 102380.49
D9: Expenses
D10: Cost of materials consumed | H10: 17487.2 | I10: 28233.3 | J10: 34585.12 | K10: 44017.16 | L10: 56981.13
D11: Changes in inventories of finished goods, stock in trade and work in progress | H11: 481.36 | I11: -949.67 | J11: -1495.59 | K11: -2848.34 | L11: -1762.96
D12: Employee benefits expense | H12: 2100.76 | I12: 4136.64 | J12: 4883.61 | K12: 6311.44 | L12: 8365.59
D13: Finance costs | H13: 561.84 | I13: 640.73 | J13: 241.23 | K13: 594.03 | L13: 621.84
D14: Depreciation and amortization expense | H14: 418.81 | I14: 1008.02 | J14: 1234.24 | K14: 1605.52 | L14: 2662.14
D15: Other expenses | H15: 5976.17 | I15: 10075.67 | J15: 11439.64 | K15: 11418.21 | L15: 13896.45
D16: Total expenses | H16: 27026.14 | I16: 43144.69 | J16: 50888.25 | K16: 61098.02 | L16: 80764.19
D17: Profit before exceptional items and tax | H17: 7172.62 | I17: 9145.04 | J17: 11217.18 | K17: 11398.52 | L17: 21616.3
D18: Exceptional items | H18: 0 | I18: 0 | J18: 0 | K18: -3208.39 | L18: 0
D19: Profit before tax | H19: =H17 -> 7172.62 | I19: =I17 -> 9145.04 | J19: 11217.18 | K19: 8190.13 | L19: 21616.3
D20: Tax expense
D21: Current tax | H21: 1756.4 | I21: 1672.15 | J21: 2637.72 | K21: 2901.53 | L21: 4918.95
D22: Deferred tax | H22: 16.33 | I22: 278.28 | J22: 250.49 | K22: 417.8 | L22: 655.58
D23: Total tax expense | H23: 1772.73 | I23: 1950.43 | J23: 2888.21 | K23: 3319.33 | L23: 5574.53
D24: Profit after tax | H24: 5399.89 | I24: 7194.61 | J24: 8328.97 | K24: 4870.8 | L24: 16041.77
D25: Other comprehensive income (OCI)
D26: Items that will not be reclassified to profit or loss
D27: Remeasurement of defined employee benefit plans | H27: -3.73 | I27: 80.65 | J27: 16.83 | K27: -6.67 | L27: -17.48
D28: Tax impact on items that will not be reclassified to of profit or loss | H28: 0.94 | I28: -20.3 | J28: 0 | K28: 1.68 | L28: 3.67
D29: Exchange differences on translation of financial statements of foreign exchange | H29: -85.18 | I29: 128.79 | J29: 290.36 | K29: -717.37 | L29: 0
D30: Other comprehensive income, net of tax | H30: =H27+H28+H29 -> -87.97 | I30: =I27+I28+I29 -> 189.14 | J30: 307.19 | K30: -722.36 | L30: -13.81
D31: Total comprehensive income for the year | H31: 5311.92 | I31: 7383.75 | J31: 8636.16 | K31: 4148.44 | L31: 16027.96
D32: Profit attributal to
D33: Owners of the company | H33: 0 | I33: 0 | J33: 0 | K33: 4277.3 | L33: 15871.36
D34: Non - controlling interest | H34: 0 | I34: 0 | J34: 0 | K34: 593.5 | L34: 170.41
D35: Other comprehensive income attributal to
D36: Owners of the company | H36: 0 | I36: 0 | J36: 0 | K36: -724.27 | L36: -12.51
D37: Non - controlling interest | H37: 0 | I37: 0 | J37: 0 | K37: 1.91 | L37: -1.3
D38: Earnings per equity share (Face value of ₹5 each)
D39: Basic (₹) | H39: 17.14 | I39: 21.03 | J39: 11.43 | K39: 5.83 | L39: 19.81
D40: Diluted (₹) | H40: 17.14 | I40: 21.03 | J40: 11.43 | K40: 5.83 | L40: 19.81
D41: Nominal value of equity shares | H41: 10 | I41: 10
...

Sheet MODEL
A1: ='HISTORICAL INFORMATION'!A1 -> ACUTAAS CHEMICALS LIMITED | J1: HISTORICAL PERIOD | M1: FORECAST PERIOD
A2: FINANCIAL STATEMENTS & DCF ANALYSIS | H2: ='HISTORICAL INFORMATION'!H4 -> 2021 | I2: ='HISTORICAL INFORMATION'!I4 -> 2022 | J2: ='HISTORICAL INFORMATION'!J4 -> 2023 | K2: ='HISTORICAL INFORMATION'!K4 -> 2024 | L2: ='HISTORICAL INFORMATION'!L4 -> 2025 | M2: ='HISTORICAL INFORMATION'!M4 -> 2026 | N2: ='HISTORICAL INFORMATION'!N4 -> 2027 | O2: ='HISTORICAL INFORMATION'!O4 -> 2028 | ... R2: ='HISTORICAL INFORMATION'!R4 -> 2031
D3: Master check | H3: =IF(H74<1,"OK",IF(H74>1,"ERROR")) -> OK | I3: =IF(I74<1,"OK",IF(I74>1,"ERROR")) -> OK | J3: =IF(J74<1,"OK",IF(J74>1,"ERROR")) -> OK | K3: =IF(K74<1,"OK",IF(K74>1,"ERROR")) -> OK | L3: =IF(L74<1,"OK",IF(L74>1,"ERROR")) -> OK | M3: =IF(M74<1,"OK",IF(M74>1,"ERROR")) -> OK | N3: =IF(N74<1,"OK",IF(N74>1,"ERROR")) -> OK | O3: =IF(O74<1,"OK",IF(O74>1,"ERROR")) -> OK | ... R3: =IF(R74<1,"OK",IF(R74>1,"ERROR")) -> OK
A5: RATIO & ASSUMPTIONS
D7: LIVE SCENARIO | E7: Base Case | F7: Units | G7: =IF(E7=SCENARIOS!D5,1,IF(MODEL!E7=SCENARIOS!D6,2,3)) -> 1
D8: Revenue growth | F8: % | H8: - | I8: =I25/H25-1 -> 0.5270785 | J8: =J25/I25-1 -> 0.18572005 | K8: =K25/J25-1 -> 0.16334419 | L8: =L25/K25-1 -> 0.40336068 | M8: {=CHOOSE(G7,SCENARIOS!H5:M5,SCENARIOS!H6:M6,SCENARIOS!H7:M7)} -> 0.31987586 | N8: 0.28788827 | O8: 0.25909944 | P8: 0.2331895 | Q8: 0.20987055 | R8: {=CHOOSE(G7,SCENARIOS!M5,SCENARIOS!M6,SCENARIOS!M7)} -> 0.18888349
D9: Costs of goods sold (% of revenue) | F9: % | H9: =-H26/H25 -> 0.52754384 | I9: =-I26/I25 -> 0.52454901 | J9: =-J26/J25 -> 0.53652795 | K9: =-K26/K25 -> 0.57380186 | L9: =-L26/L25 -> 0.5484111 | M9: =AVERAGE(H9:L9) -> 0.54216675 | N9: =M9 -> 0.54216675 | O9: =N9 -> 0.54216675 | P9: =O9 -> 0.54216675 | Q9: =P9 -> 0.54216675 | R9: =Q9 -> 0.54216675
D10: Salaries and Benefits (% of revenue) | F10: % | H10: =-H29/H25 -> 0.061676784 | I10: =-I29/I25 -> 0.079530122 | J10: =-J29/J25 -> 0.079184965 | K10: =-K29/K25 -> 0.087967447 | L10: =-L29/L25 -> 0.083084651 | M10: =AVERAGE(H10:L10) -> 0.078288794 | N10: =M10 -> 0.078288794 | O10: =N10 -> 0.078288794 | P10: =O10 -> 0.078288794 | Q10: =P10 -> 0.078288794 | R10: =Q10 -> 0.078288794
D11: Other SG&A expenses (% of revenue) | F11: % | H11: =-H30/H25 -> 0.175456 | I11: =-I30/I25 -> 0.19371259 | J11: =-J30/J25 -> 0.18548727 | K11: =-K30/K25 -> 0.15914447 | L11: =-L30/L25 -> 0.13801557 | M11: =AVERAGE(H11:L11) -> 0.17036318 | N11: =M11 -> 0.17036318 | O11: =N11 -> 0.17036318 | P11: =O11 -> 0.17036318 | Q11: =P11 -> 0.17036318 | R11: =Q11 -> 0.17036318
D12: Depreciation and amortization expense (% of PP&E) | F12: % | H12: - | I12: =-I32/I117 -> 0.062685706 | J12: =-J32/J117 -> 0.065338343 | K12: =-K32/K117 -> 0.059812455 | L12: =-L32/L117 -> 0.053695615 | M12: =AVERAGE(H12:L12) -> 0.06038303 | N12: =M12 -> 0.06038303 | O12: =N12 -> 0.06038303 | P12: =O12 -> 0.06038303 | Q12: =P12 -> 0.06038303 | R12: =Q12 -> 0.06038303
D13: Interest (% of debt) | F13: % | H13: - | I13: =-I34/I123 -> 0.046893308 | J13: =-J34/J123 -> 2.8578367 | K13: =-K34/K123 -> 1.6499458 | L13: =-L34/L123 -> 0.028702966 | M13: =8% -> 0.08 | N13: =M13 -> 0.08 | O13: =N13 -> 0.08 | P13: =O13 -> 0.08 | Q13: =P13 -> 0.08 | R13: =Q13 -> 0.08
D14: Other Income (Expenses) (% of revenue) | F14: % | H14: =H35/H25 -> 0.0040506988 | I14: =I35/I25 -> 0.0053107366 | J14: =J35/J25 -> 0.0070043106 | K14: =K35/K25 -> -0.034277176 | L14: =L35/L25 -> 0.016813797 | M14: =1% -> 0.01 | N14: =1% -> 0.01 | O14: =1% -> 0.01 | P14: =1% -> 0.01 | Q14: =1% -> 0.01 | R14: =1% -> 0.01
D15: Tax rate (% of earnings before tax) | F15: % | H15: =-H37/H36 -> 0.24715237 | I15: =-I37/I36 -> 0.21327736 | J15: =-J37/J36 -> 0.25748094 | K15: =-K37/K36 -> 0.40528417 | L15: =-L37/L36 -> 0.25788548 | M15: =AVERAGE(H15:L15) -> 0.27621606 | N15: =M15 -> 0.27621606 | O15: =N15 -> 0.27621606 | P15: =O15 -> 0.27621606 | Q15: =P15 -> 0.27621606 | R15: =Q15 -> 0.27621606
D16: Dividends payout | F16: % | H16: - | I16: - | J16: =-J99/J38 -> 0.13129715 | K16: =-K99/K38 -> 0.22442104 | L16: =-L99/L38 -> 0.076539559 | M16: =AVERAGE(H16:L16) -> 0.14408592 | N16: =M16 -> 0.14408592 | O16: =N16 -> 0.14408592 | P16: =O16 -> 0.14408592 | Q16: =P16 -> 0.14408592 | R16: =Q16 -> 0.14408592
D17: Accounts receivable | F17: Days | H17: =H47/H25*365 -> 129.33399 | I17: =I47/I25*365 -> 114.87653 | J17: =J47/J25*365 -> 136.27469 | K17: =K47/K25*365 -> 104.97727 | L17: =L47/L25*365 -> 105.30653 | M17: =AVERAGE(H17:L17) -> 118.1538 | N17: =M17 -> 118.1538 | O17: =N17 -> 118.1538 | P17: =O17 -> 118.1538 | Q17: =P17 -> 118.1538 | R17: =Q17 -> 118.1538
D18: Inventory | F18: Days | H18: =-H48/H26*365 -> 122.61712 | I18: =-I48/I26*365 -> 150.06206 | J18: =-J48/J26*365 -> 131.45592 | K18: =-K48/K26*365 -> 138.9594 | L18: =-L48/L26*365 -> 118.94305 | M18: =AVERAGE(H18:L18) -> 132.40751 | N18: =M18 -> 132.40751 | O18: =N18 -> 132.40751 | P18: =O18 -> 132.40751 | Q18: =P18 -> 132.40751 | R18: =Q18 -> 132.40751
D19: Accounts payable | F19: Days | H19: =-H61/H26*365 -> 172.20565 | I19: =-I61/I26*365 -> 158.41889 | J19: =-J61/J26*365 -> 156.68827 | K19: =-K61/K26*365 -> 119.34326 | L19: =-L61/L26*365 -> 103.14844 | M19: =AVERAGE(H19:L19) -> 141.9609 | N19: =M19 -> 141.9609 | O19: =N19 -> 141.9609 | P19: =O19 -> 141.9609 | Q19: =P19 -> 141.9609 | R19: =Q19 -> 141.9609
D20: Capital Asset Turnover Ratio | F20: Times | H20: =H25/H52 -> 2.1181372 | I20: =I25/I52 -> 2.7534968 | J20: =J25/J52 -> 2.2975986 | K20: =K25/K52 -> 1.4471528 | L20: =L25/L52 -> 1.5637816 | M20: =L20+0.3 -> 1.8637816 | N20: =M20+0.3 -> 2.1637816 | O20: =N20+0.3 -> 2.4637816 | P20: =O20+0.3 -> 2.7637816 | Q20: =P20+0.3 -> 3.0637816 | R20: =Q20+0.3 -> 3.3637816
A22: INCOME STATEMENT
B24: INCOME
D25: Revenue | F25: ₹ IN LAKHS | H25: ='HISTORICAL INFORMATION'!H6 -> 34060.79 | I25: ='HISTORICAL INFORMATION'!I6 -> 52013.5 | J25: ='HISTORICAL INFORMATION'!J6 -> 61673.45 | K25: ='HISTORICAL INFORMATION'!K6 -> 71747.45 | L25: ='HISTORICAL INFORMATION'!L6 -> 100687.55 | M25: =L25*(1+M8) -> 132895.07 | N25: =M25*(1+N8) -> 171154 | O25: =N25*(1+O8) -> 215499.9 | P25: =O25*(1+P8) -> 265752.22 | Q25: =P25*(1+Q8) -> 321525.78 | R25: =Q25*(1+R8) -> 382256.69
D26: Cost Of Goods Sold | F26: ₹ IN LAKHS | H26: =-SUM('HISTORICAL INFORMATION'!H10:H11) -> -17968.56 | I26: =-SUM('HISTORICAL INFORMATION'!I10:I11) -> -27283.63 | J26: =-SUM('HISTORICAL INFORMATION'!J10:J11) -> -33089.53 | K26: =-SUM('HISTORICAL INFORMATION'!K10:K11) -> -41168.82 | L26: =-SUM('HISTORICAL INFORMATION'!L10:L11) -> -55218.17 | M26: =-M25*M9 -> -72051.286 | N26: =-N25*N9 -> -92794.007 | O26: =-O25*O9 -> -116836.88 | P26: =-P25*P9 -> -144082.02 | Q26: =-Q25*Q9 -> -174320.59 | R26: =-R25*R9 -> -207246.87
D27: GROSS PROFIT | F27: ₹ IN LAKHS | H27: =SUM(H25:H26) -> 16092.23 | I27: =SUM(I25:I26) -> 24729.87 | J27: =SUM(J25:J26) -> 28583.92 | K27: =SUM(K25:K26) -> 30578.63 | L27: =SUM(L25:L26) -> 45469.38 | M27: =SUM(M25:M26) -> 60843.78 | N27: =SUM(N25:N26) -> 78359.99 | O27: =SUM(O25:O26) -> 98663.02 | ... R27: =SUM(R25:R26) -> 175009.82
B28: EXPENSES
D29: Salaries and Benefits | F29: ₹ IN LAKHS | H29: =-SUM('HISTORICAL INFORMATION'!H12) -> -2100.76 | I29: =-SUM('HISTORICAL INFORMATION'!I12) -> -4136.64 | J29: =-'HISTORICAL INFORMATION'!H12:L12 -> -4883.61 | K29: =-'HISTORICAL INFORMATION'!K12:M12 -> -6311.44 | L29: =-'HISTORICAL INFORMATION'!L12:N12 -> -8365.59 | M29: =-M25*M10 -> -10404.194 | N29: =-N25*N10 -> -13399.44 | O29: =-O25*O10 -> -16871.227 | P29: =-P25*P10 -> -20805.421 | Q29: =-Q25*Q10 -> -25171.866 | R29: =-R25*R10 -> -29926.415
D30: Other SG&A expenses | F30: ₹ IN LAKHS | H30: =-'HISTORICAL INFORMATION'!H15 -> -5976.17 | I30: =-'HISTORICAL INFORMATION'!I15 -> -10075.67 | J30: =-'HISTORICAL INFORMATION'!J15:L15 -> -11439.64 | K30: =-'HISTORICAL INFORMATION'!K15:M15 -> -11418.21 | L30: =-'HISTORICAL INFORMATION'!L15:N15 -> -13896.45 | M30: =-M25*M11 -> -22640.426 | N30: =-N25*N11 -> -29158.34 | O30: =-O25*O11 -> -36713.249 | P30: =-P25*P11 -> -45274.393 | Q30: =-Q25*Q11 -> -54776.155 | R30: =-R25*R11 -> -65122.467
D31: EBITDA | F31: ₹ IN LAKHS | H31: =SUM(H27:H30) -> 8015.3 | I31: =SUM(I27:I30) -> 10517.56 | J31: =SUM(J27:J30) -> 12260.67 | K31: =SUM(K27:K30) -> 12848.98 | L31: =SUM(L27:L30) -> 23207.34 | M31: =SUM(M27:M30) -> 27799.159 | N31: =SUM(N27:N30) -> 35802.211 | O31: =SUM(O27:O30) -> 45078.543 | ... R31: =SUM(R27:R30) -> 79960.941
D32: Depreciation and amortization expense | F32: ₹ IN LAKHS | H32: =-SUM('HISTORICAL INFORMATION'!H14) -> -418.81 | I32: =-SUM('HISTORICAL INFORMATION'!I14) -> -1008.02 | J32: =-'HISTORICAL INFORMATION'!J14:L14 -> -1234.24 | K32: =-'HISTORICAL INFORMATION'!K14:M14 -> -1605.52 | L32: =-'HISTORICAL INFORMATION'!L14:N14 -> -2662.14 | M32: =M119 -> -3887.8954 | N32: =N119 -> -4696.5957 | O32: =O119 -> -5480.6643 | P32: =P119 -> -6236.5667 | Q32: =Q119 -> -6957.8951 | R32: =R119 -> -7636.9785
D33: EBIT | F33: ₹ IN LAKHS | H33: =SUM(H31:H32) -> 7596.49 | I33: =SUM(I31:I32) -> 9509.54 | J33: =SUM(J31:J32) -> 11026.43 | K33: =SUM(K31:K32) -> 11243.46 | L33: =SUM(L31:L32) -> 20545.2 | M33: =SUM(M31:M32) -> 23911.263 | N33: =SUM(N31:N32) -> 31105.615 | O33: =SUM(O31:O32) -> 39597.879 | ... R33: =SUM(R31:R32) -> 72323.962
D34: Interest | F34: ₹ IN LAKHS | H34: =-SUM('HISTORICAL INFORMATION'!H13) -> -561.84 | I34: =-SUM('HISTORICAL INFORMATION'!I13) -> -640.73 | J34: =-'HISTORICAL INFORMATION'!J13:L13 -> -241.23 | K34: =-'HISTORICAL INFORMATION'!K13:M13 -> -594.03 | L34: =-'HISTORICAL INFORMATION'!L13:N13 -> -621.84 | M34: =M126 -> -103.5096 | N34: =N126 -> -103.5096 | O34: =O126 -> -103.5096 | P34: =P126 -> -103.5096 | Q34: =Q126 -> -103.5096 | R34: =R126 -> -103.5096
D35: Other Income (Expenses) | F35: ₹ IN LAKHS | H35: ='HISTORICAL INFORMATION'!H7+'HISTORICAL INFORMATION'!H18 -> 137.97 | I35: ='HISTORICAL INFORMATION'!I7+'HISTORICAL INFORMATION'!I18 -> 276.23 | J35: ='HISTORICAL INFORMATION'!J7+'HISTORICAL INFORMATION'!J18 -> 431.98 | K35: ='HISTORICAL INFORMATION'!K7+'HISTORICAL INFORMATION'!K18 -> -2459.3 | L35: ='HISTORICAL INFORMATION'!L7+'HISTORICAL INFORMATION'!L18 -> 1692.94 | M35: =M25*M14 -> 1328.9507 | N35: =N25*N14 -> 1711.54 | O35: =O25*O14 -> 2154.999 | P35: =P25*P14 -> 2657.5222 | Q35: =Q25*Q14 -> 3215.2578 | R35: =R25*R14 -> 3822.5669
D36: Earnings Before Tax | F36: ₹ IN LAKHS | H36: =SUM(H33:H35) -> 7172.62 | I36: =SUM(I33:I35) -> 9145.04 | J36: =SUM(J33:J35) -> 11217.18 | K36: =SUM(K33:K35) -> 8190.13 | L36: =SUM(L33:L35) -> 21616.3 | M36: =SUM(M33:M35) -> 25136.704 | N36: =SUM(N33:N35) -> 32713.645 | O36: =SUM(O33:O35) -> 41649.369 | ... R36: =SUM(R33:R35) -> 76043.019
D37: Taxes | F37: ₹ IN LAKHS | H37: =-'HISTORICAL INFORMATION'!H23 -> -1772.73 | I37: =-'HISTORICAL INFORMATION'!I23 -> -1950.43 | J37: =-'HISTORICAL INFORMATION'!J23:L23 -> -2888.21 | K37: =-'HISTORICAL INFORMATION'!K23:M23 -> -3319.33 | L37: =-'HISTORICAL INFORMATION'!L23:N23 -> -5574.53 | M37: =-M36*M15 -> -6943.1615 | N37: =-N36*N15 -> -9036.0343 | O37: =-O36*O15 -> -11504.225 | P37: =-P36*P15 -> -14337.777 | Q37: =-Q36*Q15 -> -17515.143 | R37: =-R36*R15 -> -21004.303
D38: Net earnings | F38: ₹ IN LAKHS | H38: =SUM(H36:H37) -> 5399.89 | I38: =SUM(I36:I37) -> 7194.61 | J38: =SUM(J36:J37) -> 8328.97 | K38: =SUM(K36:K37) -> 4870.8 | L38: =SUM(L36:L37) -> 16041.77 | M38: =SUM(M36:M37) -> 18193.543 | N38: =SUM(N36:N37) -> 23677.611 | O38: =SUM(O36:O37) -> 30145.144 | ... R38: =SUM(R36:R37) -> 55038.716
A41: BALANCE SHEET
B43: ASSESTS
C44: Current assests
D45: Cash | F45: ₹ IN LAKHS | H45: ='HISTORICAL INFORMATION'!H66 -> 268.46 | I45: ='HISTORICAL INFORMATION'!I66 -> 1029.66 | J45: ='HISTORICAL INFORMATION'!J66 -> 3053.26 | K45: ='HISTORICAL INFORMATION'!K66 -> 2970.44 | L45: ='HISTORICAL INFORMATION'!L66 -> 18522.43 | M45: =M105 -> 11007.131 | N45: =N105 -> 6446.3669 | O45: =O105 -> 6003.6823 | P45: =P105 -> 10660.517 | Q45: =Q105 -> 21434.233 | R45: =R105 -> 39327.923
D46: Bank deposits | F46: ₹ IN LAKHS | H46: ='HISTORICAL INFORMATION'!H67:L67 -> 0 | I46: ='HISTORICAL INFORMATION'!I67:M67 -> 8925.49 | J46: ='HISTORICAL INFORMATION'!J67:N67 -> 2813.76 | K46: ='HISTORICAL INFORMATION'!K67:O67 -> 2360.75 | L46: ='HISTORICAL INFORMATION'!L67:P67 -> 6370.4 | M46: =L46 -> 6370.4 | N46: =M46 -> 6370.4 | O46: =N46 -> 6370.4 | P46: =O46 -> 6370.4 | Q46: =P46 -> 6370.4 | R46: =Q46 -> 6370.4
D47: Accounts receivables | F47: ₹ IN LAKHS | H47: ='HISTORICAL INFORMATION'!H65 -> 12069.09 | I47: ='HISTORICAL INFORMATION'!I65 -> 16370.22 | J47: ='HISTORICAL INFORMATION'!J65 -> 23026.11 | K47: ='HISTORICAL INFORMATION'!K65 -> 20635.21 | L47: ='HISTORICAL INFORMATION'!L65 -> 29049.47 | M47: =M25*M17/365 -> 43019.335 | N47: =N25*N17/365 -> 55404.097 | O47: =O25*O17/365 -> 69759.268 | P47: =P25*P17/365 -> 86026.396 | Q47: =Q25*Q17/365 -> 104080.8 | R47: =R25*R17/365 -> 123739.95
...

Sheet SCENARIOS
A1: ACUTAAS CHEMICALS LIMITED
A2: SCENARIOS
C4: Scenarios | E4: Growth % | H4: 2026 | I4: 2027 | J4: 2028 | K4: 2029 | L4: 2030 | M4: 2031
D5: Base Case | E5: =AVERAGE(MODEL!H8:L8) -> 0.31987586 | H5: =E5 -> 0.31987586 | I5: =H5*(1-$E$8) -> 0.28788827 | J5: =I5*(1-$E$8) -> 0.25909944 | K5: =J5*(1-$E$8) -> 0.2331895 | L5: =K5*(1-$E$8) -> 0.20987055 | M5: =L5*(1-$E$8) -> 0.18888349
D6: Bull Case | E6: 0.35 | H6: =E6 -> 0.35 | I6: =H6*(1-$E$8) -> 0.315 | J6: =I6*(1-$E$8) -> 0.2835 | K6: =J6*(1-$E$8) -> 0.25515 | L6: =K6*(1-$E$8) -> 0.229635 | M6: =L6*(1-$E$8) -> 0.2066715
D7: Bear Case | E7: =MIN(MODEL!I8:L8) -> 0.16334419 | H7: =E7 -> 0.16334419 | I7: =H7*(1-$E$8) -> 0.14700977 | J7: =I7*(1-$E$8) -> 0.1323088 | K7: =J7*(1-$E$8) -> 0.11907792 | L7: =K7*(1-$E$8) -> 0.10717013 | M7: =L7*(1-$E$8) -> 0.096453113
D8: Annual Growth Tapering | E8: 0.1

Sheet COMP
A1: ACUTAAS CHEMICALS LIMITED
A2: COMPS VALUATION
J5: MARKET DATA | P5: FINANCIAL DATA | T5: VALUATION
H6: Price | I6: Shares | J6: Market Cap | K6: Debt | L6: Cash & | M6: EV | O6: Sales | P6: EBITDA | Q6: Earnings | S6: EV/Sales | T6: EV/EBITDA | U6: P/E
D7: Company Name | F7: Ticker | H7: (₹/Share) | I7: Lakhs | J7: ₹ Lakhs | K7: ₹ Lakhs | L7: Equivalents | M7: ₹ Lakhs | O7: ₹ Lakhs | P7: ₹ Lakhs | Q7: ₹ Lakhs | S7: x | T7: x | U7: x
D8: Neuland Laboratories Limited | F8: ='COMP DATA'!H8 -> 524558 | H8: ='COMP DATA'!I8 -> 18781.85 | I8: ='COMP DATA'!J8*10 -> 128.29946 | J8: =H8*I8 -> 2409701.2 | K8: ='COMP DATA'!K8*10 -> 30711.862 | L8: ='COMP DATA'!L8*10 -> 36185.327 | M8: =J8+K8-L8 -> 2404227.7 | O8: ='COMP DATA'!M8*10 -> 206224.3 | P8: ='COMP DATA'!N8*10 -> 58564.638 | Q8: ='COMP DATA'!O8*10 -> 37106.208 | S8: =M8/O8 -> 11.658314 | T8: =M8/P8 -> 41.05255 | U8: =J8/Q8 -> 64.940649
D9: Ipca Laboratories Limited | F9: ='COMP DATA'!H9 -> IPCALAB | H9: ='COMP DATA'!I9 -> 1696.4 | I9: ='COMP DATA'!J9*10 -> 2536.9497 | J9: =H9*I9 -> 4303681.6 | K9: ='COMP DATA'!K9*10 -> 82445.462 | L9: ='COMP DATA'!L9*10 -> 121746.6 | M9: =J9+K9-L9 -> 4264380.4 | O9: ='COMP DATA'!M9*10 -> 983352.46 | P9: ='COMP DATA'!N9*10 -> 201695.55 | Q9: ='COMP DATA'!O9*10 -> 116326.43 | S9: =M9/O9 -> 4.3365737 | T9: =M9/P9 -> 21.14266 | U9: =J9/Q9 -> 36.996592
D10: Granules India Limited | F10: ='COMP DATA'!H10 -> 532482 | H10: ='COMP DATA'!I10 -> 811.65 | I10: ='COMP DATA'!J10*10 -> 2432.6288 | J10: =H10*I10 -> 1974443.1 | K10: ='COMP DATA'!K10*10 -> 154138.33 | L10: ='COMP DATA'!L10*10 -> 96747.624 | M10: =J10+K10-L10 -> 2031833.9 | O10: ='COMP DATA'!M10*10 -> 544252.29 | P10: ='COMP DATA'!N10*10 -> 120814.27 | Q10: ='COMP DATA'!O10*10 -> 60656.785 | S10: =M10/O10 -> 3.7332574 | T10: =M10/P10 -> 16.817831 | U10: =J10/Q10 -> 32.551068
D11: Laurus Labs Limited | F11: ='COMP DATA'!H11 -> LAURUSLABS | H11: ='COMP DATA'!I11 -> 1493.3 | I11: ='COMP DATA'!J11*10 -> 5404.5959 | J11: =H11*I11 -> 8070683 | K11: ='COMP DATA'!K11*10 -> 256735.31 | L11: ='COMP DATA'!L11*10 -> 11590.643 | M11: =J11+K11-L11 -> 8315827.7 | O11: ='COMP DATA'!M11*10 -> 694510.97 | P11: ='COMP DATA'!N11*10 -> 181396.12 | Q11: ='COMP DATA'!O11*10 -> 90603.767 | S11: =M11/O11 -> 11.973645 | T11: =M11/P11 -> 45.84347 | U11: =J11/Q11 -> 89.076683
D13: Average | S13: =AVERAGE(S8:S11) -> 7.9254476 | T13: =AVERAGE(T8:T11) -> 31.214128 | U13: =AVERAGE(U8:U11) -> 55.891248
D14: Median | S14: =MEDIAN(S8:S11) -> 7.997444 | T14: =MEDIAN(T8:T11) -> 31.097605 | U14: =MEDIAN(U8:U11) -> 50.968621
D16: Acutaas Chemicals Limited | F16: ='COMP DATA'!H6 -> ACUTAAS | H16: ='COMP DATA'!I6 -> 3567.5 | I16: ='COMP DATA'!J6*10 -> 821.43255 | J16: =H16*I16 -> 2930460.6 | K16: ='COMP DATA'!K6*10 -> 3628.6664 | L16: ='COMP DATA'!L6*10 -> 22919.739 | M16: =J16+K16-L16 -> 2911169.5 | O16: ='COMP DATA'!M6*10 -> 136535.83 | P16: ='COMP DATA'!N6*10 -> 48973.906 | Q16: ='COMP DATA'!O6*10 -> 36316.871 | S16: =M16/O16 -> 21.321653 | T16: =M16/P16 -> 59.443279 | U16: =J16/Q16 -> 80.691439
D18: Metric | E18: Comps | H18: EV | I18: Net Debt | J18: Equity Value | K18: Shares | L18: Share Price
D19: EV/Revenue | E19: =S14 -> 7.997444 | H19: =E19*O16 -> 1091937.6 | I19: =K16-L16 -> -19291.072 | J19: =H19-I19 -> 1111228.7 | K19: =$I$16 -> 821.43255 | L19: =J19/K19 -> 1352.7936
D20: EV/EBITDA | E20: =T14 -> 31.097605 | H20: =E20*P16 -> 1522971.2 | I20: =I19 -> -19291.072 | J20: =H20-I20 -> 1542262.2 | K20: =$I$16 -> 821.43255 | L20: =J20/K20 -> 1877.5276
D21: P/E | E21: =U14 -> 50.968621 | H21: =+J21+I21 -> 1831729.8 | I21: =I20 -> -19291.072 | J21: =E21*Q16 -> 1851020.8 | K21: =$I$16 -> 821.43255 | L21: =J21/K21 -> 2253.4058

Sheet COMP DATA
A1: ACUTAAS CHEMICALS LIMITED
A2: COMPS DATA
D5: Company | H5: Ticker | I5: Price | J5: Shares (M) | K5: Debt (MM) | L5: Cash (MM) | M5: Sales (MM) | N5: EBITDA (MM) | O5: Net Income (MM) | P5: Tax %
D6: Acutaas Chemicals Limited | H6: ACUTAAS | I6: 3567.5 | J6: 82.143255 | K6: 362.86664 | L6: 2291.9739 | M6: 13653.583 | N6: 4897.3906 | O6: 3631.6871 | P6: 0.261756
D8: Neuland Laboratories Limited | H8: 524558 | I8: 18781.85 | J8: 12.829946 | K8: 3071.1862 | L8: 3618.5327 | M8: 20622.43 | N8: 5856.4638 | O8: 3710.6208 | P8: 0.255592
D9: Ipca Laboratories Limited | H9: IPCALAB | I9: 1696.4 | J9: 253.69497 | K9: 8244.5462 | L9: 12174.66 | M9: 98335.246 | N9: 20169.555 | O9: 11632.643 | P9: 0.243557
D10: Granules India Limited | H10: 532482 | I10: 811.65 | J10: 243.26288 | K10: 15413.833 | L10: 9674.7624 | M10: 54425.229 | N10: 12081.427 | O10: 6065.6785 | P10: 0.241993
D11: Laurus Labs Limited | H11: LAURUSLABS | I11: 1493.3 | J11: 540.45959 | K11: 25673.531 | L11: 1159.0643 | M11: 69451.097 | N11: 18139.612 | O11: 9060.3767 | P11: 0.247028
A15: Source: www.finchat.io | E15: 46205

Sheet MARKET DATA
A1: ACUTAAS CHEMICALS LIMITED
A2: EQUITY MARKET RETURN
B4: INDEX
A5: DATE | B5: CLOSE PRICE | D5: INDEX | E5: NIFTY50 TRI
A6: 46204 | B6: 36358.08
A7: 46203 | B7: 36145.88
A8: 46202 | B8: 36262.15 | D8: YEARFRAC | E8: =YEARFRAC(A6,A2482) -> 10
A9: 46198 | B9: 36428.37
A10: 46197 | B10: 36376.39
A11: 46196 | B11: 36077.17 | D11: MARKET RETURN | E11: =_xlfn.RRI(E8,B2482,B6) -> 0.125206
A12: 46195 | B12: 36489.39
A13: 46192 | B13: 36353.45
A14: 46191 | B14: 36519.02
A15: 46190 | B15: 36394.66
A16: 46189 | B16: 36248.81
A17: 46188 | B17: 36044.4
A18: 46185 | B18: 35695.33
A19: 46184 | B19: 34985.25
A20: 46183 | B20: 35065.85
A21: 46182 | B21: 35106.89
A22: 46181 | B22: 34926.96
A23: 46178 | B23: 35295.11
... A2482: 42552 | B2482: 11175.85

Sheet WACC
A1: ='HISTORICAL INFORMATION'!A1 -> ACUTAAS CHEMICALS LIMITED
A2: WEIGHTED-AVERAGE COST OF CAPITAL (WACC)
A3: ALL AMOUNTS DENOMINATED IN INR LAKHS
A6: COMPARABLE COMPANIES BETA
H8: Equity | I8: Total | J8: Debt/ | K8: Debt/ | L8: Tax | M8: Levered | N8: Unlevered
D9: Company Name | H9: Value | I9: Debt | J9: Equity | K9: Capital | L9: Rate % | M9: Beta | N9: Beta
D10: Neuland Laboratories Limited | H10: =COMP!J8 -> 2409701.2 | I10: =COMP!K8 -> 30711.862 | J10: =I10/H10 -> 0.012745091 | K10: =I10/(H10+I10) -> 0.012584698 | L10: ='COMP DATA'!P8 -> 0.255592 | M10: -0.32 | N10: =M10/(1+J10*(1-L10)) -> -0.31699252
D11: Ipca Laboratories Limited | H11: =COMP!J9 -> 4303681.6 | I11: =COMP!K9 -> 82445.462 | J11: =I11/H11 -> 0.019156962 | K11: =I11/(H11+I11) -> 0.018796871 | L11: ='COMP DATA'!P9 -> 0.243557 | M11: 0.04 | N11: =M11/(1+J11*(1-L11)) -> 0.039428634
D12: Granules India Limited | H12: =COMP!J10 -> 1974443.1 | I12: =COMP!K10 -> 154138.33 | J12: =I12/H12 -> 0.078066737 | K12: =I12/(H12+I12) -> 0.07241364 | L12: ='COMP DATA'!P10 -> 0.241993 | M12: 0.14 | N12: =M12/(1+J12*(1-L12)) -> 0.13217833
D13: Laurus Labs Limited | H13: =COMP!J11 -> 8070683 | I13: =COMP!K11 -> 256735.31 | J13: =I13/H13 -> 0.031810853 | K13: =I13/(H13+I13) -> 0.03083012 | L13: ='COMP DATA'!P11 -> 0.247028 | M13: 0.36 | N13: =M13/(1+J13*(1-L13)) -> 0.35157875
D14: AVERAGE | J14: =AVERAGE(J10:J13) -> 0.035444911 | K14: =AVERAGE(K10:K13) -> 0.033656332 | L14: =AVERAGE(L10:L13) -> 0.2470425 | M14: =AVERAGE(M10:M13) -> 0.055 | N14: =AVERAGE(N10:N13) -> 0.051548298
D15: MEDIAN | J15: =MEDIAN(J10:J13) -> 0.025483907 | K15: =MEDIAN(K10:K13) -> 0.024813495 | L15: =MEDIAN(L10:L13) -> 0.2452925 | M15: =MEDIAN(M10:M13) -> 0.09 | N15: =MEDIAN(N10:N13) -> 0.085803482
D17: Acutaas Chemicals Limited | H17: =COMP!J16 -> 2930460.6 | I17: =COMP!K16 -> 3628.6664
A20: WACC CALCULATION
C22: Target Capital Structure
D24: Proportion of Debt | H24: =K14 -> 0.033656332
D25: Proportion of Equity | H25: =1-H24 -> 0.96634367
C26: Current Capital Structure
D27: Market Cap | H27: =H17 -> 2930460.6
D28: Total Debt | H28: =I17 -> 3628.6664
D29: Debt/Equity | H29: =H28/H27 -> 0.001238258
C31: Cost of Debt
D32: Pre-Tax Cost Of Debt | H32: =MODEL!M13 -> 0.08
D33: Tax Rate | H33: =MODEL!E133 -> 0.261756
D34: After Cost of Debt | H34: =H32*(1-H33) -> 0.05905952
C36: Cost of Equity
D37: Risk Free Rate | H37: 0.067
D38: Equity Market Return | H38: ='MARKET DATA'!E11 -> 0.125206
D39: Equity Risk Premium | H39: =H38-H37 -> 0.058205996
D40: Levered Equity Beta | H40: =N15*(1+H29*(1-H33)) -> 0.085881918
D41: Cost Of Equity | H41: =H37+(H39*H40) -> 0.071998843
D43: WACC | H43: =(H34*H24)+(H41*H25) -> 0.071563352

Sheet BETA
A1: ACUTAAS CHEMICALS LIMITED
A2: HISTORICAL FINANCIAL INFORMATION
B4: INDEX | C4: % CHANGE | D4: STOCK | E4: % CHANGE
A5: DATE | B5: CLOSE PRICE | C5: MONTHLY | D5: CLOSE PRICE | E5: MONTHLY | G5: MIN | H5: =MIN(D52:D64) -> 1318.8
A6: 44440 | B6: 17618.15 | D6: 1282.5 | G6: MAX | H6: =MAX(D52:D64) -> 3546.4
A7: 44470 | B7: 17671.65 | C7: =B7/B6-1 -> 0.0030366412 | D7: 1025.05 | E7: =D7/D6-1 -> -0.20074074
A8: 44501 | B8: 16983.2 | C8: =B8/B7-1 -> -0.038957879 | D8: 901.85 | E8: =D8/D7-1 -> -0.12018926
A9: 44531 | B9: 17354.05 | C9: =B9/B8-1 -> 0.021836285 | D9: 1066.5 | E9: =D9/D8-1 -> 0.18256916 | G9: BETA | H9: =SLOPE(E7:E64,C7:C64) -> 0.23015038
A10: 44562 | B10: 17339.85 | C10: =B10/B9-1 -> -0.0008182528 | D10: 988.5 | E10: =D10/D9-1 -> -0.073136428
A11: 44593 | B11: 16793.9 | C11: =B11/B10-1 -> -0.031485278 | D11: 867.45 | E11: =D11/D10-1 -> -0.12245827
A12: 44621 | B12: 17464.75 | C12: =B12/B11-1 -> 0.039946052 | D12: 999.65 | E12: =D12/D11-1 -> 0.15240071
A13: 44652 | B13: 17102.55 | C13: =B13/B12-1 -> -0.020738917 | D13: 1134.85 | E13: =D13/D12-1 -> 0.13524734
A14: 44682 | B14: 16584.55 | C14: =B14/B13-1 -> -0.030287881 | D14: 871.45 | E14: =D14/D13-1 -> -0.23210116
A15: 44713 | B15: 15780.25 | C15: =B15/B14-1 -> -0.048496944 | D15: 876.65 | E15: =D15/D14-1 -> 0.0059670664
A16: 44743 | B16: 17158.25 | C16: =B16/B15-1 -> 0.087324345 | D16: 1038.4 | E16: =D16/D15-1 -> 0.18450921
A17: 44774 | B17: 17759.3 | C17: =B17/B16-1 -> 0.035029796 | D17: 992.65 | E17: =D17/D16-1 -> -0.044058166
A18: 44805 | B18: 17094.35 | C18: =B18/B17-1 -> -0.037442354 | D18: 912.65 | E18: =D18/D17-1 -> -0.080592354
A19: 44835 | B19: 18012.2 | C19: =B19/B18-1 -> 0.053693179 | D19: 947.65 | E19: =D19/D18-1 -> 0.03834986
A20: 44866 | B20: 18758.35 | C20: =B20/B19-1 -> 0.041424701 | D20: 974.1 | E20: =D20/D19-1 -> 0.027911149
A21: 44896 | B21: 18105.3 | C21: =B21/B20-1 -> -0.03481383 | D21: 965.45 | E21: =D21/D20-1 -> -0.0088799918
... A64: 46204 | B64: 24383.6 | C64: =B64/B63-1 -> 0.021698459 | D64: 3546.4 | E64: =D64/D63-1 -> 0.0058426456

Sheet SUMMARY
A1: ACUTAAS CHEMICALS LIMITED
A2: VALUATION SUMMARY- FOOTBALL FIELD
A4: Football Field Data
K5: Market
H6: Comps | I6: DCF | J6: 52 Week Hi/Lo | K6: Consensus
D7: High | H7: =MAX(COMP!L19:L21) -> 2253.4058 | I7: 1995.6442 | J7: =BETA!H6 -> 3546.4 | K7: 3970
D8: High | H8: =H7 -> 2253.4058 | I8: =I7 -> 1995.6442 | J8: =J7 -> 3546.4 | K8: =K7 -> 3970
D9: Low | H9: =MIN(COMP!L19:L21) -> 1352.7936 | I9: 1722.6944 | J9: =BETA!H5 -> 1318.8 | K9: 2890
D10: Low | H10: =H9 -> 1352.7936 | I10: =I9 -> 1722.6944 | J10: =J9 -> 1318.8 | K10: =K9 -> 2890
A12: Valuation Summary
